<?xml version="1.0" ?>
<!-- =================================================================================== -->
<!-- |    This document was autogenerated by xacro from robot.xacro                    | -->
<!-- |    EDITING THIS FILE BY HAND IS NOT RECOMMENDED                                 | -->
<!-- =================================================================================== -->
<robot name="z1_description">

  <link name="world"/>
  <joint name="base_static_joint" type="fixed">
    <origin rpy="0 0 0" xyz="0 0 0"/>
    <parent link="world"/>
    <child link="link00"/>
  </joint>
  <link name="link00">
    <visual>
      <origin rpy="0 0 0" xyz="0 0 0"/>
      <geometry>
        <mesh filename="render/z1_Link00.stl" scale="1 1 1"/>
      </geometry>
      <material name="black"/>
    </visual>
    <collision>
      <geometry>
        <cylinder length="0.051" radius="0.0325"/>
      </geometry>
      <origin rpy="0 0 0" xyz="0 0 0.0255"/>
    </collision>
    <inertial>
      <origin rpy="0 0 0" xyz="-0.00334984 -0.00013615 0.02495843"/>
      <mass value="0.47247481"/>
      <inertia ixx="0.00037937" ixy="3.5e-07" ixz="1.037e-05" iyy="0.00041521" iyz="9.9e-07" izz="0.00053066"/>
    </inertial>
  </link>
  <joint name="joint1" type="revolute">
    <origin rpy="0 0 0" xyz="0 0 0.0585"/>
    <parent link="link00"/>
    <child link="link01"/>
    <axis xyz="0 0 1"/>
    <dynamics damping="1.0" friction="1.0"/>
    <limit effort="30.0" lower="-2.6179938779914944" upper="2.6179938779914944" velocity="10"/>
  </joint>
  <link name="link01">
    <visual>
      <origin rpy="0 0 0" xyz="0 0 0"/>
      <material name="black"/>

      <geometry>
        <mesh filename="render/z1_Link01.stl" scale="1 1 1"/>
      </geometry>
    </visual>
    <!-- <collision>
            <geometry>
                <cylinder length="${2*motor_height}" radius="${motor_diameter}"/>
            </geometry>
            <origin rpy="0 0 0" xyz="0 0 0"/>
        </collision> -->
    <inertial>
      <origin rpy="0 0 0" xyz="2.47e-06 -0.00025198 0.02317169"/>
      <mass value="0.67332551"/>
      <inertia ixx="0.00128328" ixy="6e-08" ixz="4e-07" iyy="0.00071931" iyz="-5e-07" izz="0.00083936"/>
    </inertial>
  </link>
  <joint name="joint2" type="revolute">
    <origin rpy="0 0 0" xyz="0 0 0.045"/>
    <parent link="link01"/>
    <child link="link02"/>
    <axis xyz="0 1 0"/>
    <dynamics damping="2.0" friction="2.0"/>
    <limit effort="60.0" lower="0.0" upper="3.141592653589793" velocity="10"/>
  </joint>
  <link name="link02">
    <visual>
      <origin rpy="0 0 0" xyz="0 0 0"/>
      <material name="black"/>
      <geometry>
        <mesh filename="render/z1_Link02.stl" scale="1 1 1"/>
      </geometry>
    </visual>
    <collision>
      <geometry>
        <cylinder length="0.102" radius="0.0325"/>
      </geometry>
      <origin rpy="1.5707963267948966 0 0" xyz="0 0 0"/>
    </collision>
    <collision>
      <geometry>
        <cylinder length="0.235" radius="0.0225"/>
      </geometry>
      <origin rpy="0 1.5707963267948966 0" xyz="-0.16249999999999998 0 0"/>
    </collision>
    <collision>
      <geometry>
        <cylinder length="0.051" radius="0.0325"/>
      </geometry>
      <origin rpy="1.5707963267948966 0 0" xyz="-0.35 0 0"/>
    </collision>
    <inertial>
      <origin rpy="0 0 0" xyz="-0.11012601 0.00240029 0.00158266"/>
      <mass value="1.19132258"/>
      <inertia ixx="0.00102138" ixy="-0.00062358" ixz="-5.13e-06" iyy="0.02429457" iyz="2.1e-06" izz="0.02466114"/>
    </inertial>
  </link>
  <joint name="joint3" type="revolute">
    <origin rpy="0 0 0" xyz="-0.35 0 0"/>
    <parent link="link02"/>
    <child link="link03"/>
    <axis xyz="0 1 0"/>
    <dynamics damping="1.0" friction="1.0"/>
    <limit effort="30.0" lower="-4.782202150464463" upper="0.0" velocity="10"/>
  </joint>
  <link name="link03">
    <visual>
      <material name="black"/>
      <origin rpy="0 0 0" xyz="0 0 0"/>
      <geometry>
        <mesh filename="render/z1_Link03.stl" scale="1 1 1"/>
      </geometry>
    </visual>
    <collision>
      <geometry>
        <cylinder length="0.116" radius="0.02"/>
      </geometry>
      <origin rpy="0 1.5707963267948966 0" xyz="0.128 0 0.055"/>
    </collision>
    <collision>
      <geometry>
        <cylinder length="0.059" radius="0.0325"/>
      </geometry>
      <origin rpy="0 1.5707963267948966 0" xyz="0.2205 0 0.055"/>
    </collision>
    <inertial>
      <origin rpy="0 0 0" xyz="0.10609208 -0.00541815 0.03476383"/>
      <mass value="0.83940874"/>
      <inertia ixx="0.00108061" ixy="8.669e-05" ixz="0.00208102" iyy="0.00954238" iyz="1.332e-05" izz="0.00886621"/>
    </inertial>
  </link>
  <joint name="joint4" type="revolute">
    <origin rpy="0 0 0" xyz="0.218 0 0.057"/>
    <parent link="link03"/>
    <child link="link04"/>
    <axis xyz="0 1 0"/>
    <dynamics damping="1.0" friction="1.0"/>
    <limit effort="30.0" lower="-1.7453292519943295" upper="1.5707963267948966" velocity="10"/>
  </joint>
  <link name="link04">
    <visual>
      <origin rpy="0 0 0" xyz="0 0 0"/>
      <material name="black"/>
      <geometry>
        <mesh filename="render/z1_Link04.stl" scale="1 1 1"/>
      </geometry>
    </visual>
    <collision>
      <geometry>
        <cylinder length="0.073" radius="0.0325"/>
      </geometry>
      <origin rpy="1.5707963267948966 0 0" xyz="0.0472 0 0"/>
    </collision>
    <inertial>
      <origin rpy="0 0 0" xyz="0.04366681 0.00364738 -0.00170192"/>
      <mass value="0.56404563"/>
      <inertia ixx="0.00031576" ixy="-8.13e-05" ixz="-4.091e-05" iyy="0.00092996" iyz="5.96e-06" izz="0.00097912"/>
    </inertial>
  </link>
  <joint name="joint5" type="revolute">
    <origin rpy="0 0 0" xyz="0.07 0.0 0.0"/>
    <parent link="link04"/>
    <child link="link05"/>
    <axis xyz="0 0 1"/>
    <dynamics damping="1.0" friction="1.0"/>
    <limit effort="30.0" lower="-1.7278759594743864" upper="1.7278759594743864" velocity="10"/>
  </joint>
  <link name="link05">
    <visual>
      <origin rpy="0 0 0" xyz="0 0 0"/>
      <material name="black"/>
      <geometry>
        <mesh filename="render/z1_Link05.stl" scale="1 1 1"/>
      </geometry>
    </visual>
    <inertial>
      <origin rpy="0 0 0" xyz="0.03121533 0.0 0.00646316"/>
      <mass value="0.38938492"/>
      <inertia ixx="0.00017605" ixy="-4e-07" ixz="-5.689e-05" iyy="0.00055896" iyz="1.3e-07" izz="0.0005386"/>
    </inertial>
  </link>
  <joint name="joint6" type="revolute">
    <origin rpy="0 0 0" xyz="0.0492 0.0 0.0"/>
    <parent link="link05"/>
    <child link="link06"/>
    <axis xyz="1 0 0"/>
    <dynamics damping="1.0" friction="1.0"/>
    <limit effort="30.0" lower="-2.792526803190927" upper="2.792526803190927" velocity="10"/>
  </joint>
  <link name="link06">
    <visual>
      <origin rpy="0 0 0" xyz="0 0 0"/>
      <material name="red"/>
      <geometry>
        <mesh filename="render/z1_Link06.stl" scale="1 1 1"/>
      </geometry>
    </visual>
    <collision>
      <geometry>
        <cylinder length="0.051" radius="0.0325"/>
      </geometry>
      <origin rpy="0 1.5707963267948966 0" xyz="0.0255 0 0"/>
    </collision>
    <inertial>
      <origin rpy="0 0 0" xyz="0.0241569 -0.00017355 -0.00143876"/>
      <mass value="0.28875807"/>
      <inertia ixx="0.00018328" ixy="-1.22e-06" ixz="-5.4e-07" iyy="0.0001475" iyz="-8e-08" izz="0.0001468"/>
    </inertial>
  </link>
  
  
	<joint name = "abh_bridge" type="fixed">
		<parent link = "link06"/>
		<child link="base"/>
		<origin rpy="0 1.57079632679 0" xyz="60e-3 0 0"/>
	</joint>
    
  	<link name="base">
		<visual name="wrist_mesh">
			<origin rpy = "0 0 0" xyz = "0 0 0"/>
			<geometry>
				<mesh filename="render/wristmesh.STL"/>
			</geometry>
		</visual>		
		<inertial>	<!-- the mass and inertia here are NOT correct -->
			<mass value = "0.200"/>
			<inertia ixx="978.26e-6" ixy = "87.34e-6" ixz = "322.99e-6" iyy = "1244.78e-6" iyz = "244.74e-6" izz = "456.22e-6" />
			<origin xyz = "22.41911e-3 -0.15798201e-3 -0.01319866e-3" rpy = "0 0 0"/>
		</inertial>
	</link>
	<joint name="wrist2thumb" type="fixed">
		<parent link="base"/>
		<child link="thumb_base"/>
		<origin xyz = "24.0476665e-3 3.78124745e-3 32.32964923e-3" rpy = "3.14148426 0.08848813 3.14036612"/>
	</joint>

	<link name="thumb_base" >
		<inertial>
			<mass value = "0.400"/>
			<inertia ixx="978.26e-6" ixy = "87.34e-6" ixz = "322.99e-6" iyy = "1244.78e-6" iyz = "244.74e-6" izz = "456.22e-6" />
			<origin xyz = "22.41911e-3 -0.15798201e-3 -0.01319866e-3" rpy = "0 0 0"/>
		</inertial>
						
		<visual name="palm_mesh">
			<origin rpy = "0 0 0" xyz = "0 0 0"/>
			<geometry>
				<mesh filename="render/FB_palm_ref.STL"/>
			</geometry>
		</visual>		
	</link>
	
	
	
	<link name="index_L1" >
		<inertial>
			<mass value = "0.00635888"/>
			<inertia ixx="0.29766e-6" ixy = "-0.06447133e-6" ixz = "-0.00423315e-6" iyy = "3.6947967e-6" iyz = "0.00083028e-6" izz = "3.8176336e-6" />
			<origin xyz = "22.41911e-3 -0.15798201e-3 -0.01319866e-3" rpy = "0 0 0"/>
		</inertial>
		<visual name="index_mesh_1">
			<origin xyz = "38.472723e-3 3.257695e-3 0.000000" rpy = "0 0 0.084474"/>
			<geometry>
				<mesh filename="render/idx-F1.STL"/>
			</geometry>
		</visual>
	</link>
	<link name="index_L2" >
		<inertial>
			<mass value = "0.00645"/>
			<inertia ixx="0.82671e-6" ixy = "-1.08876e-6" ixz = "-0.00037e-6" iyy = "1.98028e-6" iyz = "0.00081e-6" izz = "2.64638e-6" />
			<origin rpy = "0 0 0" xyz = "13.36818e-3 -8.75392e-3 -0.02886e-3"/>
		</inertial>		
		<visual name="index_mesh_2">
			<origin rpy = "0 0 0" xyz = "9.1241e-3 0 0"/>
			<geometry>
				<mesh filename="render/idx-F2.STL"/>
			</geometry>
		</visual>
	</link>	
	<joint name="index_q1" type="revolute">
		<parent link="thumb_base"/>
		<child link="index_L1"/>
		<origin xyz = "-9.49e-3 -13.04e-3 -62.95e-3" rpy = "-1.982050 1.284473 -2.090591" />
		<axis xyz="0 0 1"/>
		<limit lower = "0" upper = "2.0943951" effort = "0.20" velocity = "8.0677777442"/>		<!-- angles in rad, efforts in N-m, velocity in rad/s -->
		<dynamics damping = "0.001" friction = "0.001" />	<!-- Friction coefficient is not from quantitative measurement -->
	</joint>
	<joint name="index_q2" type="revolute">
		<parent link="index_L1"/>
		<child link="index_L2"/>
		<origin xyz = "38.472723e-3 3.257695e-3 0.000000e-3" rpy = "0 0 0.084474"/>
		<axis xyz="0 0 1"/>
		<limit lower = "0.0" upper = "2.6586" effort = "0.20" velocity = "8.0677777442"/>		<!-- angles in rad, efforts in N-m, velocity in rad/s -->
		<dynamics damping = "0.001" friction = "0.001" />	<!-- Friction coefficient is not from quantitative measurement -->
		<mimic joint = "index_q1" multiplier =  "1.05851325" offset = "0.72349796"/>
	</joint>
	<link name="index_anchor"/>
	<joint name="idx_anchor" type="fixed">
		<parent link = "index_L2"/>
		<child link = "index_anchor"/>
		<origin rpy = "0 0 0" xyz = "31.5541e-3  -10.44e-3 0.14e-3"/>
	</joint>

	

	<link name="middle_L1" >
		<inertial>
			<mass value = "0.00635888"/>
			<inertia ixx="0.29766e-6" ixy = "-0.06447133e-6" ixz = "-0.00423315e-6" iyy = "3.6947967e-6" iyz = "0.00083028e-6" izz = "3.8176336e-6" />
			<origin xyz = "22.41911e-3 -0.15798201e-3 -0.01319866e-3" rpy = "0 0 0"/>
		</inertial>
		
		<visual name="middle_mesh_1">
			<origin xyz = "38.472723e-3 3.257695e-3 0.000000" rpy = "0 0 0.084474"/>
			<geometry>
				<mesh filename="render/idx-F1.STL"/>
			</geometry>
		</visual>
		
	</link>
	<link name="middle_L2" >
		<inertial>
			<mass value = "0.00645"/>
			<inertia ixx="0.82671e-6" ixy = "-1.08876e-6" ixz = "-0.00037e-6" iyy = "1.98028e-6" iyz = "0.00081e-6" izz = "2.64638e-6" />
			<origin rpy = "0 0 0" xyz = "13.36818e-3 -8.75392e-3 -0.02886e-3"/>
		</inertial>
		<visual name="middle_mesh_2">
			<origin rpy = "0 0 0" xyz = "9.1241e-3 0 0"/>
			<geometry>
				<mesh filename="render/idx-F2.STL"/>
			</geometry>
		</visual>
	</link>
	<joint name="middle_q1" type="revolute">
		<parent link="thumb_base"/>
		<child link="middle_L1"/>
		<origin xyz = "9.653191e-3 -15.310271e-3 -67.853949e-3" rpy = "-1.860531 1.308458 -1.896217" />
		<limit lower = "0" upper = "2.0943951" effort = "0.20" velocity = "8.0677777442"/>		<!-- angles in rad, efforts in N-m, velocity in rad/s -->
		<dynamics damping = "0.001" friction = "0.001" />	<!-- Friction coefficient is not from quantitative measurement -->
		<axis xyz="0 0 1"/>
	</joint>
	<joint name="middle_q2" type="revolute">
		<parent link="middle_L1"/>
		<child link="middle_L2"/>
		<origin xyz = "38.472723e-3 3.257695e-3 0.000000" rpy = "0 0 0.084474"/>
		<axis xyz="0 0 1"/>
		<limit lower = "0.0" upper = "2.6586" effort = "0.20" velocity = "8.0677777442"/>		<!-- angles in rad, efforts in N-m, velocity in rad/s -->
		<dynamics damping = "0.001" friction = "0.001" />	<!-- Friction coefficient is not from quantitative measurement -->
		<mimic joint = "middle_q1" multiplier =  "1.05851325" offset = "0.72349796"/>
	</joint>
	<link name="middle_anchor"/>
	<joint name="mid_anchor" type="fixed">
		<parent link = "middle_L2"/>
		<child link = "middle_anchor"/>
		<origin rpy = "0 0 0" xyz = "31.5541e-3  -10.44e-3 0.14e-3"/>
	</joint>





	<link name="ring_L1" >
		<inertial>
			<mass value = "0.00635888"/>
			<inertia ixx="0.29766e-6" ixy = "-0.06447133e-6" ixz = "-0.00423315e-6" iyy = "3.6947967e-6" iyz = "0.00083028e-6" izz = "3.8176336e-6" />
			<origin xyz = "22.41911e-3 -0.15798201e-3 -0.01319866e-3" rpy = "0 0 0"/>
		</inertial>
		
		<visual name="ring_mesh_1">
			<origin xyz = "38.472723e-3 3.257695e-3 0.000000" rpy = "0 0 0.084474"/>
			<geometry>
				<mesh filename="render/idx-F1.STL"/>
			</geometry>
		</visual>
	</link>
	<link name="ring_L2" >
		<inertial>
			<mass value = "0.00645"/>
			<inertia ixx="0.82671e-6" ixy = "-1.08876e-6" ixz = "-0.00037e-6" iyy = "1.98028e-6" iyz = "0.00081e-6" izz = "2.64638e-6" />
			<origin rpy = "0 0 0" xyz = "13.36818e-3 -8.75392e-3 -0.02886e-3"/>
		</inertial>
		<visual name="ring_mesh_2">
			<origin rpy = "0 0 0" xyz = "9.1241e-3 0 0"/>
			<geometry>
				<mesh filename="render/idx-F2.STL"/>
			</geometry>
		</visual>		
	</link>
	<joint name="ring_q1" type="revolute">
		<parent link="thumb_base"/>
		<child link="ring_L1"/>
		<origin xyz = "29.954260e-3 -14.212492e-3 -67.286105e-3" rpy = "-1.716598 1.321452 -1.675862" />
		<limit lower = "0" upper = "2.0943951" effort = "0.20" velocity = "8.0677777442"/>		<!-- angles in rad, efforts in N-m, velocity in rad/s -->
		<dynamics damping = "0.001" friction = "0.001" />	<!-- Friction coefficient is not from quantitative measurement -->
		<axis xyz="0 0 1"/>
	</joint>
	<joint name="ring_q2" type="revolute">
		<parent link="ring_L1"/>
		<child link="ring_L2"/>
		<origin xyz = "38.472723e-3 3.257695e-3 0.000000" rpy = "0 0 0.084474"/>
		<axis xyz="0 0 1"/>
		<limit lower = "0.0" upper = "2.6586" effort = "0.20" velocity = "8.0677777442"/>		<!-- angles in rad, efforts in N-m, velocity in rad/s -->
		<dynamics damping = "0.001" friction = "0.001" />	<!-- Friction coefficient is not from quantitative measurement -->
		<mimic joint = "ring_q1" multiplier =  "1.05851325" offset = "0.72349796"/>
	</joint>
	<link name="ring_anchor"/>
	<joint name="rng_anchor" type="fixed">
		<parent link = "ring_L2"/>
		<child link = "ring_anchor"/>
		<origin rpy = "0 0 0" xyz = "31.5541e-3  -10.44e-3 0.14e-3"/>
	</joint>



	<link name="pinky_L1" >
		<inertial>
			<mass value = "0.00635888"/>
			<inertia ixx="0.29766e-6" ixy = "-0.06447133e-6" ixz = "-0.00423315e-6" iyy = "3.6947967e-6" iyz = "0.00083028e-6" izz = "3.8176336e-6" />
			<origin xyz = "22.41911e-3 -0.15798201e-3 -0.01319866e-3" rpy = "0 0 0"/>
		</inertial>
		
		<visual name="pinky_mesh_1">
			<origin xyz = "38.472723e-3 3.257695e-3 0.000000" rpy = "0 0 0.084474"/>
			<geometry>
				<mesh filename="render/idx-F1.STL"/>
			</geometry>
		</visual>
	</link>
	<link name="pinky_L2" >
		<inertial>
			<mass value = "0.00645"/>
			<inertia ixx="0.82671e-6" ixy = "-1.08876e-6" ixz = "-0.00037e-6" iyy = "1.98028e-6" iyz = "0.00081e-6" izz = "2.64638e-6" />
			<origin rpy = "0 0 0" xyz = "13.36818e-3 -8.75392e-3 -0.02886e-3"/>
		</inertial>
		<visual name="pinky_mesh_2">
			<origin rpy = "0 0 0" xyz = "9.1241e-3 0 0"/>
			<geometry>
				<mesh filename="render/idx-F2.STL"/>
			</geometry>
		</visual>		
	</link>
	<joint name="pinky_q1" type="revolute">
		<parent link="thumb_base"/>
		<child link="pinky_L1"/>
		<origin xyz = "49.521293e-3 -11.004583e-3 -63.029065e-3" rpy = "-1.765110 1.322220 -1.658383" />
		<limit lower = "0" upper = "2.0943951" effort = "0.20" velocity = "8.0677777442"/>		<!-- angles in rad, efforts in N-m, velocity in rad/s -->
		<dynamics damping = "0.001" friction = "0.001" />	<!-- Friction coefficient is not from quantitative measurement -->
		<axis xyz="0 0 1"/>
	</joint>
	<joint name="pinky_q2" type="revolute">
		<parent link="pinky_L1"/>
		<child link="pinky_L2"/>
		<origin xyz = "38.472723e-3 3.257695e-3 0.000000" rpy = "0 0 0.084474"/>
		<limit lower = "0.0" upper = "2.6586" effort = "0.20" velocity = "8.0677777442"/>		<!-- angles in rad, efforts in N-m, velocity in rad/s -->
		<dynamics damping = "0.001" friction = "0.001" />	<!-- Friction coefficient is not from quantitative measurement -->
		<axis xyz="0 0 1"/>
		<mimic joint = "pinky_q1" multiplier =  "1.05851325" offset = "0.72349796"/>
	</joint>
	<link name="pinky_anchor"/>
	<joint name="pnky_anchor" type="fixed">
		<parent link = "pinky_L2"/>
		<child link = "pinky_anchor"/>
		<origin rpy = "0 0 0" xyz = "31.5541e-3  -10.44e-3 0.14e-3"/>
	</joint>



	<link name="thumb_L1" >
		<inertial>
			<mass value = "0.00268342"/>
			<inertia ixx="0.16931e-6" ixy = "-0.076214e-6" ixz = "-0.16959148e-6" iyy = "0.77769934e-6" iyz = "0.0156622e-6" izz = "0.7249122e-6" />
			<origin rpy = "0 0 0" xyz = "14.606e-3 -1.890854e-3 -3.1155356e-3"/>
		</inertial>
		
		<visual name="thumb_mesh_1">
			<origin xyz = "27.8283501e-3 0 -14.7507000e-3" rpy = "4.450589592585541 0 0" />
			<geometry>
				<mesh filename="render/thumb-F1.STL"/>
			</geometry>
		</visual>
		
	</link>
	<link name="thumb_L2" >
		<inertial>
			<mass value = "0.0055"/>
			<inertia ixx="4.4789082e-6" ixy = "4.4789082e-6" ixz = "-0.62144934e-6" iyy = "15.600996e-6" iyz = "-0.07466143e-6" izz = "17.908554e-6" />
			<origin rpy = "0 0 0" xyz = "30.020522e-3 5.59476e-3 -4.1504356e-3"/>
		</inertial>
		
		<visual name="thumb_mesh_2">
			<origin xyz = "65.18669e-3 23.34021e-3 -3.93483e-3" rpy = "3.141592 0 0.343830"/>
			<geometry>
				<mesh filename="render/thumb-F2.STL"/>
			</geometry>
		</visual>
		
	</link>
	<joint name="thumb_q1" type="revolute">
		<parent link="thumb_base"/>
		<child link="thumb_L1"/>
		<origin xyz = "0 0 0" rpy = "0 0 3.330437"/>
		<axis xyz="0 0 1"/>
		<limit lower = "-2.0943951" upper = "0" effort = "0.20" velocity = "8.0677777442"/>		<!-- angles in rad, efforts in N-m, velocity in rad/s -->
		<dynamics damping = "0.001" friction = "0.001" />	<!-- Friction coefficient is not from quantitative measurement -->
	</joint>
	<joint name="thumb_q2" type="revolute">
		<parent link="thumb_L1"/>
		<child link="thumb_L2"/>
		<origin xyz = "27.8283501e-3 0 -14.7507000e-3" rpy = "4.450589592585541 0 0" />
		<axis xyz="0 0 1"/>
		<limit lower = "0" upper = "2.0943951" effort = "0.20" velocity = "8.0677777442"/>		<!-- angles in rad, efforts in N-m, velocity in rad/s -->
		<dynamics damping = "0.001" friction = "0.001" />	<!-- Friction coefficient is not from quantitative measurement -->		
	</joint>
	<link name="thumb_anchor"/>
	<joint name="thmb_anchor" type="fixed">
		<parent link = "thumb_L2"/>
		<child link = "thumb_anchor"/>
		<origin rpy = "0 0 0" xyz = "52.0012259e-3  28.0086971e-3 -.884835778e-3"/>
	</joint>

  
  
  
  
  
  
  
  
  
  <transmission name="JointTrans1">
    <type>transmission_interface/SimpleTransmission</type>
    <joint name="joint1">
      <hardwareInterface>hardware_interface/EffortJointInterface</hardwareInterface>
    </joint>
    <actuator name="Actuator1">
      <hardwareInterface>hardware_interface/EffortJointInterface</hardwareInterface>
      <mechanicalReduction>1</mechanicalReduction>
    </actuator>
  </transmission>
  <transmission name="JointTrans2">
    <type>transmission_interface/SimpleTransmission</type>
    <joint name="joint2">
      <hardwareInterface>hardware_interface/EffortJointInterface</hardwareInterface>
    </joint>
    <actuator name="Actuator2">
      <hardwareInterface>hardware_interface/EffortJointInterface</hardwareInterface>
      <mechanicalReduction>1</mechanicalReduction>
    </actuator>
  </transmission>
  <transmission name="JointTrans3">
    <type>transmission_interface/SimpleTransmission</type>
    <joint name="joint3">
      <hardwareInterface>hardware_interface/EffortJointInterface</hardwareInterface>
    </joint>
    <actuator name="Actuator3">
      <hardwareInterface>hardware_interface/EffortJointInterface</hardwareInterface>
      <mechanicalReduction>1</mechanicalReduction>
    </actuator>
  </transmission>
  <transmission name="JointTrans4">
    <type>transmission_interface/SimpleTransmission</type>
    <joint name="joint4">
      <hardwareInterface>hardware_interface/EffortJointInterface</hardwareInterface>
    </joint>
    <actuator name="Actuator4">
      <hardwareInterface>hardware_interface/EffortJointInterface</hardwareInterface>
      <mechanicalReduction>1</mechanicalReduction>
    </actuator>
  </transmission>
  <transmission name="JointTrans5">
    <type>transmission_interface/SimpleTransmission</type>
    <joint name="joint5">
      <hardwareInterface>hardware_interface/EffortJointInterface</hardwareInterface>
    </joint>
    <actuator name="Actuator5">
      <hardwareInterface>hardware_interface/EffortJointInterface</hardwareInterface>
      <mechanicalReduction>1</mechanicalReduction>
    </actuator>
  </transmission>
  <transmission name="JointTrans6">
    <type>transmission_interface/SimpleTransmission</type>
    <joint name="joint6">
      <hardwareInterface>hardware_interface/EffortJointInterface</hardwareInterface>
    </joint>
    <actuator name="Actuator6">
      <hardwareInterface>hardware_interface/EffortJointInterface</hardwareInterface>
      <mechanicalReduction>1</mechanicalReduction>
    </actuator>
  </transmission>

  <ros2_control name="GazeboSystem" type="system">
    <hardware>
      <plugin>gazebo_ros2_control/GazeboSystem</plugin>
    </hardware>

    <joint name="joint1">
      <command_interface name="position">
        <param name="min">-2.6179938779914944</param>
        <param name="max">2.6179938779914944</param>
      </command_interface>
      <state_interface name="position"/>
      <state_interface name="effort"/>
      <state_interface name="velocity"/>
    </joint>

    <joint name="joint2">
      <command_interface name="position">
        <param name="min">0.0</param>
        <param name="max">3.141592653589793</param>
      </command_interface>
      <state_interface name="position"/>
      <state_interface name="effort"/>
      <state_interface name="velocity"/>
    </joint>

    <joint name="joint3">
      <command_interface name="position">
        <param name="min">-4.782202150464463</param>
        <param name="max">0.0</param>
      </command_interface>
      <state_interface name="position"/>
      <state_interface name="effort"/>
      <state_interface name="velocity"/>
    </joint>

    <joint name="joint4">
      <command_interface name="position">
        <param name="min">-1.7453292519943295</param>
        <param name="max">1.5707963267948966</param>
      </command_interface>
      <state_interface name="position"/>
      <state_interface name="effort"/>
      <state_interface name="velocity"/>
    </joint>

    <joint name="joint5">
      <command_interface name="position">
        <param name="min">-30</param>
        <param name="max">30</param>
      </command_interface>
      <state_interface name="position"/>
      <state_interface name="effort"/>
      <state_interface name="velocity"/>
    </joint>

    <joint name="joint6">
      <command_interface name="position">
        <param name="min">-30</param>
        <param name="max">30</param>
      </command_interface>
      <state_interface name="position"/>
      <state_interface name="effort"/>
      <state_interface name="velocity"/>
    </joint>
  </ros2_control>

  <gazebo>
    <plugin filename="libgazebo_ros2_control.so" name="gazebo_ros2_control">
      <parameters>$(find unitree_gazebo)/config/z1_position_control.yaml</parameters>
    </plugin>
  </gazebo>

  <gazebo reference="link00">
    <material >Gazebo/Black</material>
  </gazebo>
  <gazebo reference="link01">  
    <material >Gazebo/Black</material> 
  </gazebo>
  <gazebo reference="link02">     
    <material reference="link02">Gazebo/Black</material>
  </gazebo>
  <gazebo reference="link03">
    <material>Gazebo/Black</material>
  </gazebo>
  <gazebo reference="link04">
    <material>Gazebo/Black</material>
  </gazebo>
  <gazebo reference="link05">
    <material>Gazebo/Black</material>
  </gazebo>
  <gazebo reference="link06">
    <material>Gazebo/Red</material>
  </gazebo>

</robot>